rename_me_errors_list:  
test incfish.py: [Errno 2] No such file or directory: 'incfish_results_incorrec.out'.  
Traceback below: 
  File "/Users/nebula/Python/Tests/error_logging.py", line 26, in go_through
    i()
  File "Rename_me.py", line 431, in complete_incfish_test
    incfish.file_in_file_out_sequence()
  File "Rename_me.py", line 182, in file_in_file_out_sequence
    self.unittest_file()
  File "Rename_me.py", line 203, in unittest_file
    unittest.test_file_for_error()
  File "Rename_me.py", line 220, in test_file_for_error
    self.assertRaises(NameError, self.test_obj.check_file_output, self.test_obj.wrong_out, self.test_obj.ref_out)
  File "/Library/Frameworks/Python.framework/Versions/7.3/lib/python2.7/unittest/case.py", line 471, in assertRaises
    callableObj(*args, **kwargs)
  File "Rename_me.py", line 144, in check_file_output
    parsed_output = PT.file_parse_by_word_and_pmagpy_strip(output_file)
  File "/Users/nebula/Python/Tests/PmagPy_tests.py", line 47, in file_parse_by_word_and_pmagpy_strip
    data = file_parse_by_word(a_file)
  File "/Users/nebula/Python/Tests/PmagPy_tests.py", line 22, in file_parse_by_word
    data = open(the_file, 'rU').readlines()

test magic_select.py: [Errno 2] No such file or directory: 'magic_select_results_new.out'.  
Traceback below: 
  File "/Users/nebula/Python/Tests/error_logging.py", line 26, in go_through
    i()
  File "Rename_me.py", line 440, in complete_magic_select_test
    magic_select.file_in_file_out_sequence()
  File "Rename_me.py", line 179, in file_in_file_out_sequence
    self.check_file_output(result, self.ref_out)
  File "Rename_me.py", line 144, in check_file_output
    parsed_output = PT.file_parse_by_word_and_pmagpy_strip(output_file)
  File "/Users/nebula/Python/Tests/PmagPy_tests.py", line 47, in file_parse_by_word_and_pmagpy_strip
    data = file_parse_by_word(a_file)
  File "/Users/nebula/Python/Tests/PmagPy_tests.py", line 22, in file_parse_by_word
    data = open(the_file, 'rU').readlines()


programs with errors: ['test incfish.py', 'test magic_select.py']
random_errors_list:  
test gaussian.py: global name 'o1' is not defined.  
Traceback below: 
  File "/Users/nebula/Python/Tests/error_logging.py", line 26, in go_through
    i()
  File "Random.py", line 186, in complete_gaussian_test
    print("output 1 length: ", o1)

test fisher.py: fisher.py is producing the wrong amount of output.  
Traceback below: 
  File "/Users/nebula/Python/Tests/error_logging.py", line 26, in go_through
    i()
  File "Random.py", line 36, in complete_fisher_test
    raise NameError("fisher.py is producing the wrong amount of output")

test tk03.py: cannot concatenate 'str' and 'list' objects.  
Traceback below: 
  File "/Users/nebula/Python/Tests/error_logging.py", line 26, in go_through
    i()
  File "Random.py", line 120, in complete_tk03_test
    print "output1: " + out1


programs with errors: ['test gaussian.py', 'test fisher.py', 'test tk03.py']
extra_output_errors_list:  
testing aarm_magic.py: Wrong output -- output list did not match correct_output_list.  
Traceback below: 
  File "/Users/nebula/Python/Tests/error_logging.py", line 26, in go_through
    i()
  File "Extra_output.py", line 198, in complete_aarm_magic_test
    aarm_magic.ex_out_sequence()
  File "Extra_output.py", line 123, in ex_out_sequence
    self.standard_check_file_sequence()
  File "Extra_output.py", line 128, in standard_check_file_sequence
    self.check_file_output(self.outfile1, self.correctfile1, reference="correct")
  File "Extra_output.py", line 118, in check_file_output
    self.check_list_output(out, ref)
  File "Extra_output.py", line 77, in check_list_output
    raise NameError("Wrong output -- output list did not match correct_output_list" ) # can this message be more informative??

test orientation_magic.py: Script returned code: 1.  
Traceback below: 
  File "/Users/nebula/Python/Tests/error_logging.py", line 26, in go_through
    i()
  File "Extra_output.py", line 336, in complete_orientation_magic_test
    orientation_magic.ex_out_sequence()
  File "Extra_output.py", line 121, in ex_out_sequence
    self.run_program()
  File "Extra_output.py", line 48, in run_program
    obj = env.run(self.name, '-WD', directory, '-f', self.infile, self.tag1, self.outfile1, self.tag2, self.outfile2, self.arg1, stdin=self.stdin)
  File "/Library/Frameworks/Python.framework/Versions/7.3/lib/python2.7/site-packages/ScriptTest-1.2-py2.7.egg/scripttest/__init__.py", line 255, in run
    result.assert_no_error(quiet)
  File "/Library/Frameworks/Python.framework/Versions/7.3/lib/python2.7/site-packages/ScriptTest-1.2-py2.7.egg/scripttest/__init__.py", line 402, in assert_no_error
    "Script returned code: %s" % self.returncode)


programs with errors: ['testing aarm_magic.py', 'test orientation_magic.py']
