extra_output_errors_list:  
test thellier_magic_redo.py: [Errno 2] No such file or directory: 'thellier_magic_redo_AC_specimens_new.out'.  
Traceback below: 
  File "/Users/nebula/Python/Tests/error_logging.py", line 72, in go_through
    v()
  File "Extra_output.py", line 360, in complete_thellier_magic_redo_test
    thellier_magic_redo.standard_check_file_sequence()
  File "Extra_output.py", line 131, in standard_check_file_sequence
    self.check_file_output(self.outfile2, self.correctfile2, reference="correct")
  File "Extra_output.py", line 111, in check_file_output
    out = PT.file_parse_by_word_and_pmagpy_strip(outfile)
  File "/Users/nebula/Python/Tests/PmagPy_tests.py", line 47, in file_parse_by_word_and_pmagpy_strip
    data = file_parse_by_word(a_file)
  File "/Users/nebula/Python/Tests/PmagPy_tests.py", line 22, in file_parse_by_word
    data = open(the_file, 'rU').readlines()

test orientation_magic.py: Script returned code: 1.  
Traceback below: 
  File "/Users/nebula/Python/Tests/error_logging.py", line 72, in go_through
    v()
  File "Extra_output.py", line 336, in complete_orientation_magic_test
    orientation_magic.ex_out_sequence()
  File "Extra_output.py", line 121, in ex_out_sequence
    self.run_program()
  File "Extra_output.py", line 48, in run_program
    obj = env.run(self.name, '-WD', directory, '-f', self.infile, self.tag1, self.outfile1, self.tag2, self.outfile2, self.arg1, stdin=self.stdin)
  File "/Library/Frameworks/Python.framework/Versions/7.3/lib/python2.7/site-packages/ScriptTest-1.2-py2.7.egg/scripttest/__init__.py", line 255, in run
    result.assert_no_error(quiet)
  File "/Library/Frameworks/Python.framework/Versions/7.3/lib/python2.7/site-packages/ScriptTest-1.2-py2.7.egg/scripttest/__init__.py", line 402, in assert_no_error
    "Script returned code: %s" % self.returncode)

testing aarm_magic.py: Wrong output -- output list did not match correct_output_list.  
Traceback below: 
  File "/Users/nebula/Python/Tests/error_logging.py", line 72, in go_through
    v()
  File "Extra_output.py", line 198, in complete_aarm_magic_test
    aarm_magic.ex_out_sequence()
  File "Extra_output.py", line 123, in ex_out_sequence
    self.standard_check_file_sequence()
  File "Extra_output.py", line 128, in standard_check_file_sequence
    self.check_file_output(self.outfile1, self.correctfile1, reference="correct")
  File "Extra_output.py", line 118, in check_file_output
    self.check_list_output(out, ref)
  File "Extra_output.py", line 77, in check_list_output
    raise NameError("Wrong output -- output list did not match correct_output_list" ) # can this message be more informative??

programs with errors: ['test thellier_magic_redo.py', 'test orientation_magic.py', 'testing aarm_magic.py']

