extra_output_errors_list:  
testing aarm_magic.py: Wrong output -- output list did not match correct_output_list.  
Traceback below: 
  File "/Users/nebula/Python/Tests/error_logging.py", line 26, in go_through
    i()
  File "Extra_output.py", line 198, in complete_aarm_magic_test
    aarm_magic.ex_out_sequence()
  File "Extra_output.py", line 123, in ex_out_sequence
    self.standard_check_file_sequence()
  File "Extra_output.py", line 128, in standard_check_file_sequence
    self.check_file_output(self.outfile1, self.correctfile1, reference="correct")
  File "Extra_output.py", line 118, in check_file_output
    self.check_list_output(out, ref)
  File "Extra_output.py", line 77, in check_list_output
    raise NameError("Wrong output -- output list did not match correct_output_list" ) # can this message be more informative??

test orientation_magic.py: Script returned code: 1.  
Traceback below: 
  File "/Users/nebula/Python/Tests/error_logging.py", line 26, in go_through
    i()
  File "Extra_output.py", line 336, in complete_orientation_magic_test
    orientation_magic.ex_out_sequence()
  File "Extra_output.py", line 121, in ex_out_sequence
    self.run_program()
  File "Extra_output.py", line 48, in run_program
    obj = env.run(self.name, '-WD', directory, '-f', self.infile, self.tag1, self.outfile1, self.tag2, self.outfile2, self.arg1, stdin=self.stdin)
  File "/Library/Frameworks/Python.framework/Versions/7.3/lib/python2.7/site-packages/ScriptTest-1.2-py2.7.egg/scripttest/__init__.py", line 255, in run
    result.assert_no_error(quiet)
  File "/Library/Frameworks/Python.framework/Versions/7.3/lib/python2.7/site-packages/ScriptTest-1.2-py2.7.egg/scripttest/__init__.py", line 402, in assert_no_error
    "Script returned code: %s" % self.returncode)

programs with errors: ['testing aarm_magic.py', 'test orientation_magic.py']

