STARTING HERE
CLEANING HOUSE
-
TRYING
 - 
testing help for angle.py
488
Help message successfully called
-
CLEANING HOUSE
-
Non-WD program about to run:
angle.py -f /Users/nebula/Python/Basic_input_output/angle.dat -F /Users/nebula/Python/Basic_input_output/angle_results_new.out None None None None None None stdin=None
Script result: angle.py -f /Users/nebula/Python/Basic_input_output/angle.dat -F /Users/nebula/Python/Basic_input_output/angle_results_new.out None None None None None None
  return code: 1
-- stderr: --------------------
Traceback (most recent call last):
  File "/Users/nebula/PmagPy/angle.py", line 66, in <module>
    main() 
  File "/Users/nebula/PmagPy/angle.py", line 33, in main
    out=open(o,'w')
IOError: [Errno 2] No such file or directory: '/Users/nebula/Python/Basic_input_output/angle_results_new.out'

<function complete_angle_test at 0x536130> failed donut
i, ex:  <function complete_angle_test at 0x536130> Script returned code: 1
type(ex) <type 'exceptions.AssertionError'>
ex.args ('Script returned code: 1',)
0 <type 'exceptions.AssertionError'>
1 Script returned code: 1
2 <traceback object at 0x534710>
TRYING
 - 
testing help for zeq.py
845
Help message successfully called
-
CLEANING HOUSE
-
Non-WD program about to run:
zeq.py -f /Users/nebula/Python/Basic_input_output/zeq_example.dat -F None -u C None None None None stdin=q
Script result: zeq.py -f /Users/nebula/Python/Basic_input_output/zeq_example.dat -F None -u C None None None None
  return code: 1
-- stderr: --------------------
Traceback (most recent call last):
  File "/Users/nebula/PmagPy/zeq.py", line 130, in <module>
    main() # run the main program
  File "/Users/nebula/PmagPy/zeq.py", line 44, in main
    f=open(file,'rU')
IOError: [Errno 2] No such file or directory: '/Users/nebula/Python/Basic_input_output/zeq_example.dat'

<function complete_zeq_test at 0x5365f0> failed donut
i, ex:  <function complete_zeq_test at 0x5365f0> Script returned code: 1
type(ex) <type 'exceptions.AssertionError'>
ex.args ('Script returned code: 1',)
0 <type 'exceptions.AssertionError'>
1 Script returned code: 1
2 <traceback object at 0x594a58>
TRYING
 - 
testing help for chartmaker.py
411
Help message successfully called
-
CLEANING HOUSE
-
Non-WD program about to run:
chartmaker.py -f None -F None None None None None None None stdin=q
output is plot
new files created:  {'chart.txt': <FoundFile ./new-test-output:chart.txt>}
Checking stdout output
chartmaker.py output as expected
-
Testing: chartmaker.py with incorrect short output, expecting error
Checking stdout output
Output was: 
wrong
Output should have been: 
{'chart.txt': <FoundFile ./new-test-output:chart.txt>}
Error raised
Error expected
-
Testing: chartmaker.py with incorrect short output, expecting error
Checking stdout output
Output was: 
wrong
Output should have been: 
{'chart.txt': <FoundFile ./new-test-output:chart.txt>}
Error raised
Error expected
-
TRYING
 - 
Testing di_eq.py
CLEANING HOUSE
-
Non-WD program about to run:
di_eq.py -f /Users/nebula/Python/Basic_input_output/di_eq_example.dat -F None None None None None None None stdin=None
Script result: di_eq.py -f /Users/nebula/Python/Basic_input_output/di_eq_example.dat -F None None None None None None None
  return code: 1
-- stderr: --------------------
Traceback (most recent call last):
  File "/Users/nebula/PmagPy/di_eq.py", line 40, in <module>
    main() 
  File "/Users/nebula/PmagPy/di_eq.py", line 27, in main
    DI=numpy.loadtxt(file,dtype=numpy.float)
  File "/Library/Frameworks/Python.framework/Versions/7.3/lib/python2.7/site-packages/numpy/lib/npyio.py", line 690, in loadtxt
    fh = iter(open(fname, 'U'))
IOError: [Errno 2] No such file or directory: '/Users/nebula/Python/Basic_input_output/di_eq_example.dat'

<function complete_di_eq_test at 0x536670> failed donut
i, ex:  <function complete_di_eq_test at 0x536670> Script returned code: 1
type(ex) <type 'exceptions.AssertionError'>
ex.args ('Script returned code: 1',)
0 <type 'exceptions.AssertionError'>
1 Script returned code: 1
2 <traceback object at 0x594b48>
TRYING
 - 
CLEANING HOUSE
-
Non-WD program about to run:
azdip_magic.py -f /Users/nebula/Python/Basic_input_output/azdip_magic_example.dat -F None -Fsa azdip_magic_output.out -mcd FS-FD:SO-POM -loc Northern Iceland stdin=False
Script result: azdip_magic.py -f /Users/nebula/Python/Basic_input_output/azdip_magic_example.dat -F None -Fsa azdip_magic_output.out -mcd FS-FD:SO-POM -loc Northern Iceland
  return code: 1
-- stderr: --------------------
Traceback (most recent call last):
  File "/Users/nebula/PmagPy/azdip_magic.py", line 164, in <module>
    main()
  File "/Users/nebula/PmagPy/azdip_magic.py", line 123, in main
    azfile=open(orient_file,'rU')
IOError: [Errno 2] No such file or directory: '/Users/nebula/Python/Basic_input_output/azdip_magic_example.dat'

<function complete_azdip_magic_test at 0x5366b0> failed donut
i, ex:  <function complete_azdip_magic_test at 0x5366b0> Script returned code: 1
type(ex) <type 'exceptions.AssertionError'>
ex.args ('Script returned code: 1',)
0 <type 'exceptions.AssertionError'>
1 Script returned code: 1
2 <traceback object at 0x594b70>
TRYING
 - 
Script result: combine_magic.py -WD /Users/nebula/Python/Basic_input_output -F combine_magic_output_new.out -f combine_magic_input_1.dat combine_magic_input_2.dat
  return code: 1
-- stderr: --------------------
Traceback (most recent call last):
  File "/Users/nebula/PmagPy/combine_magic.py", line 65, in <module>
    main()
  File "/Users/nebula/PmagPy/combine_magic.py", line 63, in main
    pmag.magic_write(output,Recs,file_type)
  File "/Users/nebula/PmagPy/pmag.py", line 987, in magic_write
    pmag_out=open(ofile,'w')
IOError: [Errno 2] No such file or directory: '/Users/nebula/Python/Basic_input_output/combine_magic_output_new.out'

-- stdout: --------------------
File  /Users/nebula/Python/Basic_input_output/combine_magic_input_1.dat  read in with  0  records
File  /Users/nebula/Python/Basic_input_output/combine_magic_input_2.dat  read in with  0  records

<function complete_combine_magic_test at 0x5366f0> failed donut
i, ex:  <function complete_combine_magic_test at 0x5366f0> Script returned code: 1
type(ex) <type 'exceptions.AssertionError'>
ex.args ('Script returned code: 1',)
0 <type 'exceptions.AssertionError'>
1 Script returned code: 1
2 <traceback object at 0x594a80>
TRYING
 - 
Checking stdout output
cont_rot.py output as expected
-
testing help for cont_rot.py
2854
Help message successfully called
-
Testing: cont_rot.py with incorrect short output, expecting error
Checking stdout output
Output was: 
wrong
Output should have been: 
{'Cont_rot.pdf': <FoundFile ./new-test-output:Cont_rot.pdf>}
Error raised
Error expected
-
TRYING
 - 
testing help for customize_criteria.py
522
Help message successfully called
-
CLEANING HOUSE
-
Non-WD program about to run:
customize_criteria.py -f /Users/nebula/Python/Basic_input_output/customize_criteria_example.dat -F /Users/nebula/Python/Basic_input_output/customize_criteria_outfile.out None None None None None None stdin=1
output is file: /Users/nebula/Python/Basic_input_output/customize_criteria_outfile.out
checking file output, using: /Users/nebula/Python/Basic_input_output/customize_criteria_outfile.out AND customize_criteria_output_correct.out
parsing file: /Users/nebula/Python/Basic_input_output/customize_criteria_outfile.out
<function complete_customize_criteria_test at 0x5367f0> failed donut
i, ex:  <function complete_customize_criteria_test at 0x5367f0> [Errno 2] No such file or directory: '/Users/nebula/Python/Basic_input_output/customize_criteria_outfile.out'
type(ex) <type 'exceptions.IOError'>
ex.args (2, 'No such file or directory')
0 <type 'exceptions.IOError'>
1 [Errno 2] No such file or directory: '/Users/nebula/Python/Basic_input_output/customize_criteria_outfile.out'
2 <traceback object at 0x594cb0>
TRYING
 - 
CLEANING HOUSE
-
WD program about to run:
('download_magic.py', '-WD', '/Users/nebula/Python/Basic_input_output', '-f', 'download_magic_example.dat', '-F', None, None, None, None, None, None, None, 'stdin=y')
Script result: download_magic.py -WD /Users/nebula/Python/Basic_input_output -f download_magic_example.dat -F None None None None None None None
  return code: 1
-- stderr: --------------------
Traceback (most recent call last):
  File "/Users/nebula/PmagPy/download_magic.py", line 142, in <module>
    main()
  File "/Users/nebula/PmagPy/download_magic.py", line 37, in main
    f=open(dir_path+'/'+file,'rU')
IOError: [Errno 2] No such file or directory: '/Users/nebula/Python/Basic_input_output/download_magic_example.dat'

<function complete_download_magic_test at 0x536770> failed donut
i, ex:  <function complete_download_magic_test at 0x536770> Script returned code: 1
type(ex) <type 'exceptions.AssertionError'>
ex.args ('Script returned code: 1',)
0 <type 'exceptions.AssertionError'>
1 Script returned code: 1
2 <traceback object at 0x5a05d0>
TRYING
 - 
CLEANING HOUSE
-
Non-WD program about to run:
dipole_pinc.py -f /Users/nebula/Python/Basic_input_output/dipole_pinc_example.dat -F None None None None None None None stdin=None
Script result: dipole_pinc.py -f /Users/nebula/Python/Basic_input_output/dipole_pinc_example.dat -F None None None None None None None
  return code: 1
-- stderr: --------------------
Traceback (most recent call last):
  File "/Users/nebula/PmagPy/dipole_pinc.py", line 41, in <module>
    main()        
  File "/Users/nebula/PmagPy/dipole_pinc.py", line 25, in main
    f=open(file,'rU')
IOError: [Errno 2] No such file or directory: '/Users/nebula/Python/Basic_input_output/dipole_pinc_example.dat'

<function complete_dipole_pinc_test at 0x536830> failed donut
i, ex:  <function complete_dipole_pinc_test at 0x536830> Script returned code: 1
type(ex) <type 'exceptions.AssertionError'>
ex.args ('Script returned code: 1',)
0 <type 'exceptions.AssertionError'>
1 Script returned code: 1
2 <traceback object at 0x5a0698>
TRYING
 - 
CLEANING HOUSE
-
Non-WD program about to run:
dipole_plat.py -f /Users/nebula/Python/Basic_input_output/dipole_plat_example.dat -F None None None None None None None stdin=None
Script result: dipole_plat.py -f /Users/nebula/Python/Basic_input_output/dipole_plat_example.dat -F None None None None None None None
  return code: 1
-- stderr: --------------------
Traceback (most recent call last):
  File "/Users/nebula/PmagPy/dipole_plat.py", line 41, in <module>
    main()        
  File "/Users/nebula/PmagPy/dipole_plat.py", line 25, in main
    f=open(file,'rU')
IOError: [Errno 2] No such file or directory: '/Users/nebula/Python/Basic_input_output/dipole_plat_example.dat'

<function complete_dipole_plat_test at 0x536870> failed donut
i, ex:  <function complete_dipole_plat_test at 0x536870> Script returned code: 1
type(ex) <type 'exceptions.AssertionError'>
ex.args ('Script returned code: 1',)
0 <type 'exceptions.AssertionError'>
1 Script returned code: 1
2 <traceback object at 0x5a0710>
TRYING
 - 
Testing grab magic
CLEANING HOUSE
-
WD program about to run:
('grab_magic_key.py', '-WD', '/Users/nebula/Python/Basic_input_output', '-f', 'grab_magic_key_er_sites.txt', '-F', None, '-key', 'site_lat', None, None, None, None, 'stdin=None')
output is stdout: 
bad file name

bad file name

checking output (in list form)
output_list:         ['bad', 'file', 'name']
correct_output_list: ['42.60264', '42.60264', '42.60352', '42.60104', '42.73656', '42.8418', '42.8657', '42.92031', '42.56857', '42.49964', '42.49962', '42.50001', '42.52872', '42.45559', '42.48923', '42.46186', '42.69156', '42.65289', '43.30504', '43.36817', '43.42133', '43.8859', '43.84273', '43.53289', '43.57494', '44.15663', '44.18629']
Comparing two lists
Output contained:    bad
but should have had: 42.60264
Error raised
<function complete_grab_magic_key_test at 0x5368b0> failed donut
i, ex:  <function complete_grab_magic_key_test at 0x5368b0> Wrong output
type(ex) <type 'exceptions.NameError'>
ex.args ('Wrong output',)
0 <type 'exceptions.NameError'>
1 Wrong output
2 <traceback object at 0x5a0648>
TRYING
 - 
testing help for incfish.py
683
Help message successfully called
-
CLEANING HOUSE
-
Non-WD program about to run:
incfish.py -f /Users/nebula/Python/Basic_input_output/incfish_example_inc.dat -F /Users/nebula/Python/Basic_input_output/incfish_results_new.out None None None None None None stdin=None
Script result: incfish.py -f /Users/nebula/Python/Basic_input_output/incfish_example_inc.dat -F /Users/nebula/Python/Basic_input_output/incfish_results_new.out None None None None None None
  return code: 1
-- stderr: --------------------
Traceback (most recent call last):
  File "/Users/nebula/PmagPy/incfish.py", line 59, in <module>
    main()
  File "/Users/nebula/PmagPy/incfish.py", line 43, in main
    inc=numpy.loadtxt(file)
  File "/Library/Frameworks/Python.framework/Versions/7.3/lib/python2.7/site-packages/numpy/lib/npyio.py", line 690, in loadtxt
    fh = iter(open(fname, 'U'))
IOError: [Errno 2] No such file or directory: '/Users/nebula/Python/Basic_input_output/incfish_example_inc.dat'

<function complete_incfish_test at 0x5368f0> failed donut
i, ex:  <function complete_incfish_test at 0x5368f0> Script returned code: 1
type(ex) <type 'exceptions.AssertionError'>
ex.args ('Script returned code: 1',)
0 <type 'exceptions.AssertionError'>
1 Script returned code: 1
2 <traceback object at 0x5a0760>
TRYING
 - 
testing help for magic_select.py
1166
Help message successfully called
-
CLEANING HOUSE
-
WD program about to run:
('magic_select.py', '-WD', '/Users/nebula/Python/Basic_input_output', '-f', 'magic_select_example.txt', '-F', 'magic_select_results_new.out', '-key', 'magic_method_codes', 'LP-DIR-AF', 'has', None, None, 'stdin=None')
output is file: magic_select_results_new.out
checking file output, using: magic_select_results_new.out AND magic_select_results_correct.out
parsing file: magic_select_results_new.out
<function complete_magic_select_test at 0x536930> failed donut
i, ex:  <function complete_magic_select_test at 0x536930> [Errno 2] No such file or directory: 'magic_select_results_new.out'
type(ex) <type 'exceptions.IOError'>
ex.args (2, 'No such file or directory')
0 <type 'exceptions.IOError'>
1 [Errno 2] No such file or directory: 'magic_select_results_new.out'
2 <traceback object at 0x5a0828>
TRYING
 - 
Testing nrm_specimens_magic.py
testing help for nrm_specimens_magic.py
959
Help message successfully called
-
CLEANING HOUSE
-
Non-WD program about to run:
nrm_specimens_magic.py -f /Users/nebula/Python/Basic_input_output/nrm_specimens_magic_measurements.txt -F /Users/nebula/Python/Basic_input_output/nrm_specimens_results_new.out -fsa /Users/nebula/Python/Basic_input_output/nrm_specimens_magic_er_samples.txt -crd g None None stdin=None
stdout:bad_file
This is not a valid er_samples file 

<function complete_nrm_specimens_magic_test at 0x536970> failed donut
i, ex:  <function complete_nrm_specimens_magic_test at 0x536970> nrm_specimens_magic.py encountered an invalid file
type(ex) <type 'exceptions.NameError'>
ex.args ('nrm_specimens_magic.py encountered an invalid file',)
0 <type 'exceptions.NameError'>
1 nrm_specimens_magic.py encountered an invalid file
2 <traceback object at 0x5a0878>
TRYING
 - 
CLEANING HOUSE
-
Non-WD program about to run:
sundec.py -f /Users/nebula/Python/Basic_input_output/sundec_example.dat -F None None None None None None None stdin=None
Script result: sundec.py -f /Users/nebula/Python/Basic_input_output/sundec_example.dat -F None None None None None None None
  return code: 1
-- stderr: --------------------
Traceback (most recent call last):
  File "/Users/nebula/PmagPy/sundec.py", line 75, in <module>
    main()
  File "/Users/nebula/PmagPy/sundec.py", line 46, in main
    f=open(file,'rU')
IOError: [Errno 2] No such file or directory: '/Users/nebula/Python/Basic_input_output/sundec_example.dat'

<function complete_sundec_test at 0x5369b0> failed donut
i, ex:  <function complete_sundec_test at 0x5369b0> Script returned code: 1
type(ex) <type 'exceptions.AssertionError'>
ex.args ('Script returned code: 1',)
0 <type 'exceptions.AssertionError'>
1 Script returned code: 1
2 <traceback object at 0x5a0918>
TRYING
 - 
CLEANING HOUSE
-
Non-WD program about to run:
pca.py -f /Users/nebula/Python/Basic_input_output/pca_example.dat -F None -dir L 1 10 None None stdin=None
Script result: pca.py -f /Users/nebula/Python/Basic_input_output/pca_example.dat -F None -dir L 1 10 None None
  return code: 1
-- stderr: --------------------
Traceback (most recent call last):
  File "/Users/nebula/PmagPy/pca.py", line 71, in <module>
    main()
  File "/Users/nebula/PmagPy/pca.py", line 41, in main
    f=open(file,'rU')
IOError: [Errno 2] No such file or directory: '/Users/nebula/Python/Basic_input_output/pca_example.dat'

<function complete_pca_test at 0x5369f0> failed donut
i, ex:  <function complete_pca_test at 0x5369f0> Script returned code: 1
type(ex) <type 'exceptions.AssertionError'>
ex.args ('Script returned code: 1',)
0 <type 'exceptions.AssertionError'>
1 Script returned code: 1
2 <traceback object at 0x5a09b8>
TRYING
 - 
CLEANING HOUSE
-
Non-WD program about to run:
scalc.py -f /Users/nebula/Python/Basic_input_output/scalc_example.txt -F None None None None None None None stdin=None
Script result: scalc.py -f /Users/nebula/Python/Basic_input_output/scalc_example.txt -F None None None None None None None
  return code: 1
-- stderr: --------------------
Traceback (most recent call last):
  File "/Users/nebula/PmagPy/scalc.py", line 135, in <module>
    main()
  File "/Users/nebula/PmagPy/scalc.py", line 47, in main
    f=open(in_file,'rU')
IOError: [Errno 2] No such file or directory: '/Users/nebula/Python/Basic_input_output/scalc_example.txt'

<function complete_scalc_test at 0x536a30> failed donut
i, ex:  <function complete_scalc_test at 0x536a30> Script returned code: 1
type(ex) <type 'exceptions.AssertionError'>
ex.args ('Script returned code: 1',)
0 <type 'exceptions.AssertionError'>
1 Script returned code: 1
2 <traceback object at 0x5a0a08>
TRYING
 - 
CLEANING HOUSE
-
Non-WD program about to run:
scalc_magic.py -f /Users/nebula/Python/Basic_input_output/scalc_magic_example.txt -F None None None None None None None stdin=None
output is stdout: 
0    -0.0     90.0 

0    -0.0     90.0 

checking output (in list form)
output_list:         ['0', '-0.0', '90.0']
correct_output_list: ['13', '17.8', '90.0']
Comparing two lists
Output contained:    0
but should have had: 13
Error raised
<function complete_scalc_magic_test at 0x536a70> failed donut
i, ex:  <function complete_scalc_magic_test at 0x536a70> Wrong output
type(ex) <type 'exceptions.NameError'>
ex.args ('Wrong output',)
0 <type 'exceptions.NameError'>
1 Wrong output
2 <traceback object at 0x5a0760>
TRYING
 - 
CLEANING HOUSE
-
Non-WD program about to run:
vgp_di.py -f /Users/nebula/Python/Basic_input_output/vgp_di_example.dat -F None None None None None None None stdin=None
Script result: vgp_di.py -f /Users/nebula/Python/Basic_input_output/vgp_di_example.dat -F None None None None None None None
  return code: 1
-- stderr: --------------------
Traceback (most recent call last):
  File "/Users/nebula/PmagPy/vgp_di.py", line 73, in <module>
    main()
  File "/Users/nebula/PmagPy/vgp_di.py", line 65, in main
    f=open(file,'rU')
IOError: [Errno 2] No such file or directory: '/Users/nebula/Python/Basic_input_output/vgp_di_example.dat'

<function complete_vgp_di_test at 0x536af0> failed donut
i, ex:  <function complete_vgp_di_test at 0x536af0> Script returned code: 1
type(ex) <type 'exceptions.AssertionError'>
ex.args ('Script returned code: 1',)
0 <type 'exceptions.AssertionError'>
1 Script returned code: 1
2 <traceback object at 0x5a0918>
TRYING
 - 
CLEANING HOUSE
-
Non-WD program about to run:
watsonsF.py -f /Users/nebula/Python/Basic_input_output/watsonsF_example_file1.dat -F None -f2 /Users/nebula/Python/Basic_input_output/watsonsF_example_file2.dat None None None None stdin=None
Script result: watsonsF.py -f /Users/nebula/Python/Basic_input_output/watsonsF_example_file1.dat -F None -f2 /Users/nebula/Python/Basic_input_output/watsonsF_example_file2.dat None None None None
  return code: 1
-- stderr: --------------------
Traceback (most recent call last):
  File "/Users/nebula/PmagPy/watsonsF.py", line 76, in <module>
    main()
  File "/Users/nebula/PmagPy/watsonsF.py", line 39, in main
    f=open(file1,'rU')
IOError: [Errno 2] No such file or directory: '/Users/nebula/Python/Basic_input_output/watsonsF_example_file1.dat'

<function complete_watsonsF_test at 0x536b30> failed donut
i, ex:  <function complete_watsonsF_test at 0x536b30> Script returned code: 1
type(ex) <type 'exceptions.AssertionError'>
ex.args ('Script returned code: 1',)
0 <type 'exceptions.AssertionError'>
1 Script returned code: 1
2 <traceback object at 0x5a0a30>
TRYING
 - 
testing help for apwp.py
840
Help message successfully called
-
CLEANING HOUSE
-
Non-WD program about to run:
apwp.py -f /Users/nebula/Python/Basic_input_output/apwp_example.dat -F /Users/nebula/Python/Basic_input_output/apwp_results_new.out None None None None None None stdin=None
Script result: apwp.py -f /Users/nebula/Python/Basic_input_output/apwp_example.dat -F /Users/nebula/Python/Basic_input_output/apwp_results_new.out None None None None None None
  return code: 1
-- stderr: --------------------
Traceback (most recent call last):
  File "/Users/nebula/PmagPy/apwp.py", line 113, in <module>
    main()
  File "/Users/nebula/PmagPy/apwp.py", line 43, in main
    out=open(outfile,'w')
IOError: [Errno 2] No such file or directory: '/Users/nebula/Python/Basic_input_output/apwp_results_new.out'

<function complete_apwp_test at 0x536b70> failed donut
i, ex:  <function complete_apwp_test at 0x536b70> Script returned code: 1
type(ex) <type 'exceptions.AssertionError'>
ex.args ('Script returned code: 1',)
0 <type 'exceptions.AssertionError'>
1 Script returned code: 1
2 <traceback object at 0x5a0788>
TRYING
 - 
testing help for b_vdm.py
451
Help message successfully called
-
CLEANING HOUSE
-
Non-WD program about to run:
b_vdm.py -f /Users/nebula/Python/Basic_input_output/b_vdm_example.dat -F /Users/nebula/Python/Basic_input_output/b_vdm_results_new.out None None None None None None stdin=None
Script result: b_vdm.py -f /Users/nebula/Python/Basic_input_output/b_vdm_example.dat -F /Users/nebula/Python/Basic_input_output/b_vdm_results_new.out None None None None None None
  return code: 1
-- stderr: --------------------
Traceback (most recent call last):
  File "/Users/nebula/PmagPy/b_vdm.py", line 68, in <module>
    main() 
  File "/Users/nebula/PmagPy/b_vdm.py", line 42, in main
    f=open(file,'rU')
IOError: [Errno 2] No such file or directory: '/Users/nebula/Python/Basic_input_output/b_vdm_example.dat'

<function complete_b_vdm_test at 0x536bb0> failed donut
i, ex:  <function complete_b_vdm_test at 0x536bb0> Script returned code: 1
type(ex) <type 'exceptions.AssertionError'>
ex.args ('Script returned code: 1',)
0 <type 'exceptions.AssertionError'>
1 Script returned code: 1
2 <traceback object at 0x5a0760>
TRYING
 - 
testing help for cart_dir.py
570
Help message successfully called
-
CLEANING HOUSE
-
Non-WD program about to run:
cart_dir.py -f /Users/nebula/Python/Basic_input_output/cart_dir_example.dat -F /Users/nebula/Python/Basic_input_output/cart_dir_results_new.out None None None None None None stdin=None
Script result: cart_dir.py -f /Users/nebula/Python/Basic_input_output/cart_dir_example.dat -F /Users/nebula/Python/Basic_input_output/cart_dir_results_new.out None None None None None None
  return code: 1
-- stderr: --------------------
Traceback (most recent call last):
  File "/Users/nebula/PmagPy/cart_dir.py", line 63, in <module>
    main() 
  File "/Users/nebula/PmagPy/cart_dir.py", line 34, in main
    outfile=open(ofile,'w')
IOError: [Errno 2] No such file or directory: '/Users/nebula/Python/Basic_input_output/cart_dir_results_new.out'

<function complete_cart_dir_test at 0x536bf0> failed donut
i, ex:  <function complete_cart_dir_test at 0x536bf0> Script returned code: 1
type(ex) <type 'exceptions.AssertionError'>
ex.args ('Script returned code: 1',)
0 <type 'exceptions.AssertionError'>
1 Script returned code: 1
2 <traceback object at 0x5a0468>
TRYING
 - 
testing help for convert_samples.py
486
Help message successfully called
-
CLEANING HOUSE
-
Non-WD program about to run:
convert_samples.py -f /Users/nebula/Python/Basic_input_output/convert_samples_example.dat -F /Users/nebula/Python/Basic_input_output/convert_samples_Northern_Iceland.txt None None None None None None stdin=None
output is file: /Users/nebula/Python/Basic_input_output/convert_samples_Northern_Iceland.txt
checking file output, using: /Users/nebula/Python/Basic_input_output/convert_samples_Northern_Iceland.txt AND convert_samples_results_correct.out
parsing file: /Users/nebula/Python/Basic_input_output/convert_samples_Northern_Iceland.txt
<function complete_convert_samples_test at 0x536c30> failed donut
i, ex:  <function complete_convert_samples_test at 0x536c30> [Errno 2] No such file or directory: '/Users/nebula/Python/Basic_input_output/convert_samples_Northern_Iceland.txt'
type(ex) <type 'exceptions.IOError'>
ex.args (2, 'No such file or directory')
0 <type 'exceptions.IOError'>
1 [Errno 2] No such file or directory: '/Users/nebula/Python/Basic_input_output/convert_samples_Northern_Iceland.txt'
2 <traceback object at 0x5a05d0>
TRYING
 - 
testing help for di_geo.py
552
Help message successfully called
-
CLEANING HOUSE
-
Non-WD program about to run:
di_geo.py -f /Users/nebula/Python/Basic_input_output/di_geo_example.dat -F /Users/nebula/Python/Basic_input_output/di_geo_results_new.out None None None None None None stdin=None
Script result: di_geo.py -f /Users/nebula/Python/Basic_input_output/di_geo_example.dat -F /Users/nebula/Python/Basic_input_output/di_geo_results_new.out None None None None None None
  return code: 1
-- stderr: --------------------
Traceback (most recent call last):
  File "/Users/nebula/PmagPy/di_geo.py", line 59, in <module>
    main()
  File "/Users/nebula/PmagPy/di_geo.py", line 32, in main
    out=open(ofile,'w')
IOError: [Errno 2] No such file or directory: '/Users/nebula/Python/Basic_input_output/di_geo_results_new.out'

<function complete_di_geo_test at 0x536c70> failed donut
i, ex:  <function complete_di_geo_test at 0x536c70> Script returned code: 1
type(ex) <type 'exceptions.AssertionError'>
ex.args ('Script returned code: 1',)
0 <type 'exceptions.AssertionError'>
1 Script returned code: 1
2 <traceback object at 0x5a07b0>
TRYING
 - 
testing help for di_tilt.py
592
Help message successfully called
-
CLEANING HOUSE
-
Non-WD program about to run:
di_tilt.py -f /Users/nebula/Python/Basic_input_output/di_tilt_example.dat -F /Users/nebula/Python/Basic_input_output/di_tilt_results_new.out None None None None None None stdin=None
Script result: di_tilt.py -f /Users/nebula/Python/Basic_input_output/di_tilt_example.dat -F /Users/nebula/Python/Basic_input_output/di_tilt_results_new.out None None None None None None
  return code: 1
-- stderr: --------------------
Traceback (most recent call last):
  File "/Users/nebula/PmagPy/di_tilt.py", line 60, in <module>
    main()
  File "/Users/nebula/PmagPy/di_tilt.py", line 34, in main
    out=open(ofile,'w')
IOError: [Errno 2] No such file or directory: '/Users/nebula/Python/Basic_input_output/di_tilt_results_new.out'

<function complete_di_tilt_test at 0x536cb0> failed donut
i, ex:  <function complete_di_tilt_test at 0x536cb0> Script returned code: 1
type(ex) <type 'exceptions.AssertionError'>
ex.args ('Script returned code: 1',)
0 <type 'exceptions.AssertionError'>
1 Script returned code: 1
2 <traceback object at 0x5a0580>
TRYING
 - 
testing help for dir_cart.py
552
Help message successfully called
-
CLEANING HOUSE
-
Non-WD program about to run:
dir_cart.py -f /Users/nebula/Python/Basic_input_output/dir_cart_example.dat -F /Users/nebula/Python/Basic_input_output/dir_cart_results_new.out None None None None None None stdin=None
Script result: dir_cart.py -f /Users/nebula/Python/Basic_input_output/dir_cart_example.dat -F /Users/nebula/Python/Basic_input_output/dir_cart_results_new.out None None None None None None
  return code: 1
-- stderr: --------------------
Traceback (most recent call last):
  File "/Users/nebula/PmagPy/dir_cart.py", line 64, in <module>
    main() 
  File "/Users/nebula/PmagPy/dir_cart.py", line 36, in main
    out=open(ofile,'w')
IOError: [Errno 2] No such file or directory: '/Users/nebula/Python/Basic_input_output/dir_cart_results_new.out'

<function complete_dir_cart_test at 0x536cf0> failed donut
i, ex:  <function complete_dir_cart_test at 0x536cf0> Script returned code: 1
type(ex) <type 'exceptions.AssertionError'>
ex.args ('Script returned code: 1',)
0 <type 'exceptions.AssertionError'>
1 Script returned code: 1
2 <traceback object at 0x5a05f8>
TRYING
 - 
testing help for di_rot.py
522
Help message successfully called
-
CLEANING HOUSE
-
Non-WD program about to run:
di_rot.py -f /Users/nebula/Python/Basic_input_output/di_rot_example.dat -F /Users/nebula/Python/Basic_input_output/di_rot_results_new.out None None None None None None stdin=None
Script result: di_rot.py -f /Users/nebula/Python/Basic_input_output/di_rot_example.dat -F /Users/nebula/Python/Basic_input_output/di_rot_results_new.out None None None None None None
  return code: 1
-- stderr: --------------------
Traceback (most recent call last):
  File "/Users/nebula/PmagPy/di_rot.py", line 65, in <module>
    main()
  File "/Users/nebula/PmagPy/di_rot.py", line 34, in main
    data=numpy.loadtxt(infile)
  File "/Library/Frameworks/Python.framework/Versions/7.3/lib/python2.7/site-packages/numpy/lib/npyio.py", line 690, in loadtxt
    fh = iter(open(fname, 'U'))
IOError: [Errno 2] No such file or directory: '/Users/nebula/Python/Basic_input_output/di_rot_example.dat'

<function complete_di_rot_test at 0x536d30> failed donut
i, ex:  <function complete_di_rot_test at 0x536d30> Script returned code: 1
type(ex) <type 'exceptions.AssertionError'>
ex.args ('Script returned code: 1',)
0 <type 'exceptions.AssertionError'>
1 Script returned code: 1
2 <traceback object at 0x5a0850>
TRYING
 - 
testing help for di_vgp.py
756
Help message successfully called
-
CLEANING HOUSE
-
Non-WD program about to run:
di_vgp.py -f /Users/nebula/Python/Basic_input_output/di_vgp_example.dat -F /Users/nebula/Python/Basic_input_output/di_vgp_results_new.out None None None None None None stdin=None
Script result: di_vgp.py -f /Users/nebula/Python/Basic_input_output/di_vgp_example.dat -F /Users/nebula/Python/Basic_input_output/di_vgp_results_new.out None None None None None None
  return code: 1
-- stderr: --------------------
Traceback (most recent call last):
  File "/Users/nebula/PmagPy/di_vgp.py", line 87, in <module>
    main()
  File "/Users/nebula/PmagPy/di_vgp.py", line 41, in main
    out=open(ofile,'w')
IOError: [Errno 2] No such file or directory: '/Users/nebula/Python/Basic_input_output/di_vgp_results_new.out'

<function complete_di_vgp_test at 0x536d70> failed donut
i, ex:  <function complete_di_vgp_test at 0x536d70> Script returned code: 1
type(ex) <type 'exceptions.AssertionError'>
ex.args ('Script returned code: 1',)
0 <type 'exceptions.AssertionError'>
1 Script returned code: 1
2 <traceback object at 0x5a0670>
TRYING
 - 
testing help for eigs_s.py
524
Help message successfully called
-
CLEANING HOUSE
-
Non-WD program about to run:
eigs_s.py -f /Users/nebula/Python/Basic_input_output/eigs_s_example.dat -F /Users/nebula/Python/Basic_input_output/eigs_s_results_new.out None None None None None None stdin=None
Script result: eigs_s.py -f /Users/nebula/Python/Basic_input_output/eigs_s_example.dat -F /Users/nebula/Python/Basic_input_output/eigs_s_results_new.out None None None None None None
  return code: 1
-- stderr: --------------------
Traceback (most recent call last):
  File "/Users/nebula/PmagPy/eigs_s.py", line 63, in <module>
    main() 
  File "/Users/nebula/PmagPy/eigs_s.py", line 38, in main
    f=open(file,'rU')
IOError: [Errno 2] No such file or directory: '/Users/nebula/Python/Basic_input_output/eigs_s_example.dat'

<function complete_eigs_s_test at 0x536db0> failed donut
i, ex:  <function complete_eigs_s_test at 0x536db0> Script returned code: 1
type(ex) <type 'exceptions.AssertionError'>
ex.args ('Script returned code: 1',)
0 <type 'exceptions.AssertionError'>
1 Script returned code: 1
2 <traceback object at 0x5a06c0>
TRYING
 - 
testing help for eq_di.py
331
Help message successfully called
-
CLEANING HOUSE
-
Non-WD program about to run:
eq_di.py -f /Users/nebula/Python/Basic_input_output/eq_di_example.dat -F /Users/nebula/Python/Basic_input_output/eq_di_results_new.out None None None None None None stdin=None
Script result: eq_di.py -f /Users/nebula/Python/Basic_input_output/eq_di_example.dat -F /Users/nebula/Python/Basic_input_output/eq_di_results_new.out None None None None None None
  return code: 1
-- stderr: --------------------
Traceback (most recent call last):
  File "/Users/nebula/PmagPy/eq_di.py", line 64, in <module>
    main() 
  File "/Users/nebula/PmagPy/eq_di.py", line 28, in main
    f=open(file,'rU')
IOError: [Errno 2] No such file or directory: '/Users/nebula/Python/Basic_input_output/eq_di_example.dat'

<function complete_eq_di_test at 0x536df0> failed donut
i, ex:  <function complete_eq_di_test at 0x536df0> Script returned code: 1
type(ex) <type 'exceptions.AssertionError'>
ex.args ('Script returned code: 1',)
0 <type 'exceptions.AssertionError'>
1 Script returned code: 1
2 <traceback object at 0x5a0800>
TRYING
 - 
testing help for gobing.py
442
Help message successfully called
-
CLEANING HOUSE
-
Non-WD program about to run:
gobing.py -f /Users/nebula/Python/Basic_input_output/gobing_example.out -F /Users/nebula/Python/Basic_input_output/gobing_results_new.out None None None None None None stdin=None
Script result: gobing.py -f /Users/nebula/Python/Basic_input_output/gobing_example.out -F /Users/nebula/Python/Basic_input_output/gobing_results_new.out None None None None None None
  return code: 1
-- stderr: --------------------
Traceback (most recent call last):
  File "/Users/nebula/PmagPy/gobing.py", line 57, in <module>
    main()
  File "/Users/nebula/PmagPy/gobing.py", line 32, in main
    f=open(file,'rU')
IOError: [Errno 2] No such file or directory: '/Users/nebula/Python/Basic_input_output/gobing_example.out'

<function complete_gobing_test at 0x536e30> failed donut
i, ex:  <function complete_gobing_test at 0x536e30> Script returned code: 1
type(ex) <type 'exceptions.AssertionError'>
ex.args ('Script returned code: 1',)
0 <type 'exceptions.AssertionError'>
1 Script returned code: 1
2 <traceback object at 0x5a05d0>
TRYING
 - 
testing help for gofish.py
528
Help message successfully called
-
CLEANING HOUSE
-
Non-WD program about to run:
gofish.py -f /Users/nebula/Python/Basic_input_output/gofish_example.out -F /Users/nebula/Python/Basic_input_output/gofish_results_new.out None None None None None None stdin=None
Script result: gofish.py -f /Users/nebula/Python/Basic_input_output/gofish_example.out -F /Users/nebula/Python/Basic_input_output/gofish_results_new.out None None None None None None
  return code: 1
-- stderr: --------------------
Traceback (most recent call last):
  File "/Users/nebula/PmagPy/gofish.py", line 63, in <module>
    main()
  File "/Users/nebula/PmagPy/gofish.py", line 39, in main
    f=open(file,'rU')
IOError: [Errno 2] No such file or directory: '/Users/nebula/Python/Basic_input_output/gofish_example.out'

<function complete_gofish_test at 0x536e70> failed donut
i, ex:  <function complete_gofish_test at 0x536e70> Script returned code: 1
type(ex) <type 'exceptions.AssertionError'>
ex.args ('Script returned code: 1',)
0 <type 'exceptions.AssertionError'>
1 Script returned code: 1
2 <traceback object at 0x5a0738>
TRYING
 - 
testing help for gokent.py
525
Help message successfully called
-
CLEANING HOUSE
-
Non-WD program about to run:
gokent.py -f /Users/nebula/Python/Basic_input_output/gokent_example.out -F /Users/nebula/Python/Basic_input_output/gokent_results_new.out None None None None None None stdin=None
Script result: gokent.py -f /Users/nebula/Python/Basic_input_output/gokent_example.out -F /Users/nebula/Python/Basic_input_output/gokent_results_new.out None None None None None None
  return code: 1
-- stderr: --------------------
Traceback (most recent call last):
  File "/Users/nebula/PmagPy/gokent.py", line 64, in <module>
    main()
  File "/Users/nebula/PmagPy/gokent.py", line 34, in main
    f=open(file,'rU')
IOError: [Errno 2] No such file or directory: '/Users/nebula/Python/Basic_input_output/gokent_example.out'

<function complete_gokent_test at 0x536eb0> failed donut
i, ex:  <function complete_gokent_test at 0x536eb0> Script returned code: 1
type(ex) <type 'exceptions.AssertionError'>
ex.args ('Script returned code: 1',)
0 <type 'exceptions.AssertionError'>
1 Script returned code: 1
2 <traceback object at 0x5a0a30>
TRYING
 - 
testing help for goprinc.py
559
Help message successfully called
-
CLEANING HOUSE
-
Non-WD program about to run:
goprinc.py -f /Users/nebula/Python/Basic_input_output/goprinc_example.dat -F /Users/nebula/Python/Basic_input_output/goprinc_results_new.out None None None None None None stdin=None
Script result: goprinc.py -f /Users/nebula/Python/Basic_input_output/goprinc_example.dat -F /Users/nebula/Python/Basic_input_output/goprinc_results_new.out None None None None None None
  return code: 1
-- stderr: --------------------
Traceback (most recent call last):
  File "/Users/nebula/PmagPy/goprinc.py", line 65, in <module>
    main()
  File "/Users/nebula/PmagPy/goprinc.py", line 36, in main
    f=open(file,'rU')
IOError: [Errno 2] No such file or directory: '/Users/nebula/Python/Basic_input_output/goprinc_example.dat'

<function complete_goprinc_test at 0x536ef0> failed donut
i, ex:  <function complete_goprinc_test at 0x536ef0> Script returned code: 1
type(ex) <type 'exceptions.AssertionError'>
ex.args ('Script returned code: 1',)
0 <type 'exceptions.AssertionError'>
1 Script returned code: 1
2 <traceback object at 0x5a0828>
TRYING
 - 
testing help for igrf.py
1292
Help message successfully called
-
CLEANING HOUSE
-
Non-WD program about to run:
igrf.py -f /Users/nebula/Python/Basic_input_output/igrf_example.dat -F /Users/nebula/Python/Basic_input_output/igrf_results_new.out None None None None None None stdin=None
Script result: igrf.py -f /Users/nebula/Python/Basic_input_output/igrf_example.dat -F /Users/nebula/Python/Basic_input_output/igrf_results_new.out None None None None None None
  return code: 1
-- stderr: --------------------
Traceback (most recent call last):
  File "/Users/nebula/PmagPy/igrf.py", line 133, in <module>
    main()
  File "/Users/nebula/PmagPy/igrf.py", line 53, in main
    input=numpy.loadtxt(file)
  File "/Library/Frameworks/Python.framework/Versions/7.3/lib/python2.7/site-packages/numpy/lib/npyio.py", line 690, in loadtxt
    fh = iter(open(fname, 'U'))
IOError: [Errno 2] No such file or directory: '/Users/nebula/Python/Basic_input_output/igrf_example.dat'

<function complete_igrf_test at 0x536f30> failed donut
i, ex:  <function complete_igrf_test at 0x536f30> Script returned code: 1
type(ex) <type 'exceptions.AssertionError'>
ex.args ('Script returned code: 1',)
0 <type 'exceptions.AssertionError'>
1 Script returned code: 1
2 <traceback object at 0x5a0940>
TRYING
 - 
testing help for k15_s.py
771
Help message successfully called
-
CLEANING HOUSE
-
Non-WD program about to run:
k15_s.py -f /Users/nebula/Python/Basic_input_output/k15_s_example.dat -F /Users/nebula/Python/Basic_input_output/k15_s_results_new.out None None None None None None stdin=None
Script result: k15_s.py -f /Users/nebula/Python/Basic_input_output/k15_s_example.dat -F /Users/nebula/Python/Basic_input_output/k15_s_results_new.out None None None None None None
  return code: 1
-- stderr: --------------------
Traceback (most recent call last):
  File "/Users/nebula/PmagPy/k15_s.py", line 94, in <module>
    main() 
  File "/Users/nebula/PmagPy/k15_s.py", line 53, in main
    f=open(file,'rU')
IOError: [Errno 2] No such file or directory: '/Users/nebula/Python/Basic_input_output/k15_s_example.dat'

<function complete_k15_s_test at 0x536f70> failed donut
i, ex:  <function complete_k15_s_test at 0x536f70> Script returned code: 1
type(ex) <type 'exceptions.AssertionError'>
ex.args ('Script returned code: 1',)
0 <type 'exceptions.AssertionError'>
1 Script returned code: 1
2 <traceback object at 0x5a0a08>
TRYING
 - 
testing help for mk_redo.py
